Workbook

Sheet MF_Summary
F1: UNITS | G1: NAV | K1: birla | L1: 818919 | M1: 1017159 | N1: =M1-L1 -> 198240 | Q1: Sahana | U1: PPF
K2: franklin | L2: 572784 | M2: 611678 | N2: =M2-L2 -> 38894 | Q2: 40452 | R2: 1 | S2: 32 | U2: 2012-13 | V2: 1 | Y2: 29129 | Z2: 1
A3: 3 | B3: Canara Robeco Equity Debt Allocation Direct-G | D3: 174000 | F3: 1038.993 | G3: 168.22 | H3: =F3*G3 -> 174779.4 | I3: =H3-D3 -> 779.40246 | K3: HDFC | L3: 941985 | M3: 1029630 | N3: =M3-L3 -> 87645 | Q3: 40817 | R3: 2 | S3: 33 | U3: 2013-14 | V3: 2 | Y3: 29495 | Z3: 2
A4: 13 | B4: Tata Hybrid Equity Fund | D4: 113500 | F4: 755.928 | G4: 185.1145 | H4: =F4*G4 -> 139933.23 | I4: =H4-D4 -> 26433.234 | K4: icici | L4: 535261 | M4: 573274 | N4: =M4-L4 -> 38013 | Q4: 41183 | R4: 3 | S4: 34 | U4: 2014-15 | V4: 3 | Y4: 29860 | Z4: 3
A5: 44244 | B5: HDFC Hybrid Equity Fund | D5: 198500 | F5: 3850.105 | G5: 73.193 | H5: =F5*G5 -> 281800.74 | I5: =H5-D5 -> 83300.735 | J5: Done | K5: mirae | L5: 495351 | M5: 563037 | N5: =M5-L5 -> 67686 | Q5: 41548 | R5: 4 | S5: 35 | U5: 2015-16 | V5: 4 | Y5: 30225 | Z5: 4
A6: 44244 | B6: Aditya Birla Sun Life Balanced 95 Fund | D6: 124000 | F6: 181.16 | G6: 996.8 | H6: =F6*G6 -> 180580.29 | I6: =H6-D6 -> 56580.288 | J6: Done | K6: quantum | L6: 1561475 | M6: 1737734 | N6: =M6-L6 -> 176259 | Q6: 41913 | R6: 5 | S6: 36 | U6: 2016-17 | V6: 5 | Y6: 30590 | Z6: 5
A7: 44244 | B7: Mirae Asset Hybrid Equity Direct-G | D7: 100000 | F7: 5884.776 | G7: 21.125 | H7: =F7*G7 -> 124315.89 | I7: =H7-D7 -> 24315.893 | K7: Parag | L7: 1000000 | M7: 1008339 | N7: =M7-L7 -> 8339 | P7: 1618.538 | Q7: 42278 | R7: 6 | S7: 37 | U7: 2017-18 | V7: 6 | Y7: 30956 | Z7: 6
A8: transfer6 | B8: Franklin India Equity Hybrid Fund | D8: 59000 | F8: 482.22 | G8: 165.79 | H8: =F8*G8 -> 79947.254 | I8: =H8-D8 -> 20947.254 | L8: =SUM(L1:L7) -> 5925775 | M8: =SUM(M1:M7) -> 6540851 | P8: -453.662 | Q8: 42644 | R8: 7 | S8: 38 | U8: 2018-19 | V8: 7 | Y8: 31321 | Z8: 7
J9: nav | K9: =SUM(I6:I27) -> 3022122.5 | M9: =M8-L8 -> 615076 | P9: =SUM(P7:P8) -> 1164.876 | Q9: 43009 | R9: 8 | S9: 39 | U9: 2019-20 | V9: 8 | Y9: 31686 | Z9: 8
A10: Redeem2 | B10: BNP Paribas Substantial Equity Hybrid Fund | D10: 100000 | F10: 7072.486 | G10: 16.85 | H10: =F10*G10 -> 119171.39 | I10: =H10-D10 -> 19171.389 | J10: nav | Q10: 43374 | R10: 9 | S10: 40 | U10: 2020-21 | V10: 9 | Y10: 32051 | Z10: 9
A11: Redeem5 | B11: DSPBR Equity & Bond Direct-G | D11: 100000 | F11: 544.04 | G11: 215.013 | H11: =F11*G11 -> 116975.67 | I11: =H11-D11 -> 16975.673 | L11: 572784 | N11: 54.8058 | O11: 453.662 | P11: =N11*O11 -> 24863.309 | Q11: 43739 | R11: 10 | S11: 41 | U11: 2021-22 | V11: 10 | Y11: 32417 | Z11: 10
A12: Redeem3 | B12: L&T Hybrid Equity Fund | D12: 10000 | F12: 363.187 | G12: 34.743 | H12: =F12*G12 -> 12618.206 | I12: =H12-D12 -> 2618.2059 | J12: nav | P12: 6 | Q12: 44105 | R12: 11 | S12: 42 | U12: 2022-23 | V12: 11 | Y12: 32782 | Z12: 11
A13: Redeem7 | B13: Principal Hybrid Equity Direct-G | D13: 35000 | F13: 440.904 | G13: 101.72 | H13: =F13*G13 -> 44848.755 | I13: =H13-D13 -> 9848.7549 | J13: nav | M13: 1540907 | P13: 7 | Q13: 44470 | R13: 12 | S13: 43 | U13: 2023 | V13: 12 | Y13: 33147 | Z13: 12
A14: Redeem4 | B14: Reliance Equity Hybrid Fund | D14: 117070 | F14: 2498.411 | G14: 60.607 | H14: =F14*G14 -> 151421.2 | I14: =H14-D14 -> 34351.195 | J14: nav | K14: 24530 | L14: 4578993 | M14: =SUM(H5:H7) -> 586696.92 | P14: 8 | Q14: 44835 | R14: 13 | S14: 44 | U14: 2024 | V14: 13 | Y14: 33512 | Z14: 13
A15: Redeem8 | B15: SBI Equity Hybrid Fund | D15: 50000 | F15: 315.371 | G15: 183.9539 | H15: =F15*G15 -> 58013.725 | I15: =H15-D15 -> 8013.7254 | J15: nav | L15: =SUM(H6:H19) -> 1158845.2 | M15: =SUM(M13:M14) -> 2127603.9 | P15: 9 | Q15: 45200 | R15: 14 | S15: 45 | U15: 2025 | V15: 14 | Y15: 33878 | Z15: 14
A16: Redeem9 | B16: Axis | D16: 60000 | F16: 5107.195 | G16: 13.48 | H16: =F16*G16 -> 68844.989 | I16: =H16-D16 -> 8844.9886 | J16: nav | L16: 660000 | P16: 10 | Q16: 45566 | R16: 15 | S16: 46 | U16: 2026 | V16: 15 | Y16: 34243 | Z16: 15
A17: Redeem1 | B17: Kotak | D17: 60000 | F17: 2035.16 | G17: 36.842 | H17: =F17*G17 -> 74979.365 | I17: =H17-D17 -> 14979.365 | J17: nav | K17: 43302 | N17: -120000 | P17: 1st | Q17: 45931 | R17: 16 | S17: 47 | Y17: 34608 | Z17: 16
A18: Redeem11 | B18: Motilal | D18: 60000 | F18: 4927.11 | G18: 14.15 | H18: =F18*G18 -> 69718.606 | I18: =H18-D18 -> 9718.6065 | J18: nav | M18: 887919 | P18: 2nd | Q18: 46296 | R18: 17 | S18: 48 | Y18: 34973 | Z18: 17
A19: Redeem10 | B19: Sundaram | D19: 50000 | F19: 477.58 | G19: 120.21 | H19: =F19*G19 -> 57409.892 | I19: =H19-D19 -> 7409.8918 | J19: nav | P19: 13 | Q19: 46661 | R19: 18 | S19: 49 | Y19: 35339 | Z19: 18
B20: ICICI Equity Arbitrage | D20: 630000 | F20: 23883.519 | G20: 27.9222 | H20: =F20*G20 -> 666880.39 | I20: =H20-D20 -> 36880.394 | P20: 14 | Q20: 47027 | R20: 19
B21: HDFC mid-cap opportunity fund | C21: midcap | D21: 144000 | F21: 2441.841 | G21: 60.255 | H21: =F21*G21 -> 147133.13 | I21: =H21-D21 -> 3133.1295 | P21: 15 | Q21: 47392 | R21: 20
A22: 1 | B22: Franklin India Prima Fund | C22: midcap | D22: 139353 | F22: 136.131 | G22: 1043.0163 | H22: =F22*G22 -> 141986.85 | I22: =H22-D22 -> 2633.8519 | J22: mid-cap | P22: 16 | Q22: 47757 | R22: 21
A23: 2 | J23: mid-cap | Q23: 48122 | R23: 22 | S23: 50 | Y23: 35704 | Z23: 19
D24: =SUM(D6:D20) -> 1555070 | H24: =SUM(H6:H20) -> 1825725.6 | I24: =SUM(I10:I20) -> 168812.19 | Q24: 48488 | R24: 23 | S24: 51 | Y24: 36069 | Z24: 20
J25: 122242 | K25: 39000 | L25: 30000 | Q25: 48853 | R25: 24 | S25: 52 | Y25: 36434 | Z25: 21
D26: 630000 | E26: =SUM(D24:D26) -> 2185070 | G26: =I26-E26 -> 290757.62 | H26: 650102 | I26: =SUM(H24:H26) -> 2475827.6 | S26: 53 | Y26: 36800 | Z26: 22
A27: 14 | B27: Birla FoF - Aggressive | D27: 111900 | F27: 9038.287 | G27: 23.562 | H27: =F27*G27 -> 212960.12 | I27: =H27-D27 -> 101060.12 | K27: 42937 | L27: withdraw | M27: 212960.11 | S27: 54 | Y27: 37165 | Z27: 23
K28: 225255 | N28: 1017.7453 | S28: 55 | Y28: 37530 | Z28: 24
K29: 286854 | Y29: 37895 | Z29: 25
A30: 3 | B30: SUNDARAM MID CAP FUND DIRECT GROWTH | D30: 135000 | F30: 288.166 | G30: 475.0881 | H30: =F30*G30 -> 136904.24 | I30: =H30-D30 -> 1904.2374 | J30: mid-cap | N30: debt | O30: =SUM(H27,K28,K29) -> 725069.12 | Y30: 38261 | Z30: 26
A31: 4 | B31: Motilal Oswal Most Focused multicap 35 Fund | D31: 263398 | F31: 10301.416 | G31: 27.8889 | H31: =F31*G31 -> 287295.16 | I31: =H31-D31 -> 23897.161 | J31: multicap | L31: withdraw | M31: 287292.29 | N31: cash | O31: =SUM(K14,K32,K33,K34,M33) -> 2069734 | Y31: 38626 | Z31: 27
A32: 5 | B32: Mirae Asset India Equity Fund | C32: Multicap' | D32: 135000 | F32: 2766.363 | G32: 53.926 | H32: =F32*G32 -> 149178.89 | I32: =H32-D32 -> 14178.891 | J32: largecap | K32: 281087 | L32: transfer | M32: 151083.41 | Y32: 38991 | Z32: 28
A33: 6 | B33: QLTE | C33: Multicap' | D33: 177000 | F33: 3352.179 | G33: 52.953 | H33: =F33*G33 -> 177507.93 | I33: =H33-D33 -> 507.93459 | J33: largecap | K33: 1595402 | N33: 982035 | Y33: 39356 | Z33: 29
A34: 7 | B34: Aditya birla frontline equity fund | C34: largecap | D34: 120000 | F34: 652.04 | G34: 225.46 | H34: =F34*G34 -> 147008.94 | I34: =H34-D34 -> 27008.938 | J34: largecap | K34: 168715 | L34: transfer | M34: 154935.48 | N34: 400000 | O34: 154935.48 | Y34: 39722 | Z34: 30
A35: 8 | B35: Franklin india bluechip fund | C35: largecap | D35: 15000 | F35: 32.558 | G35: 472.5081 | H35: =F35*G35 -> 15383.919 | I35: =H35-D35 -> 383.91872 | J35: largecap | L35: withdraw | M35: 15383.92 | N35: =SUM(N33:N34) -> 1382035 | Y35: 40087 | Z35: 31
I36: =SUM(I2:I35) -> 3200517 | X36: 1 | Y36: 40452 | Z36: 32
K37: =SUM(D21:D35) -> 3425721 | N37: 5000000 | O37: =SUM(H38,K34,K33,K32,K29,K28,K14,O14) -> 8895268.8 | P37: =N37-O37 -> -3895268.8 | X37: 2 | Y37: 40817 | Z37: 33
D38: =SUM(D6:D35) -> 4980791 | H38: =SUM(H2:H35) -> 6313425.8 | X38: 3 | Y38: 41183 | Z38: 34
X39: 4 | Y39: 41548 | Z39: 35
A40: 8 | B40: ICICI Prudential Equity Income Fund Direct Plan Cumulative | D40: 10000 | F40: 795.861 | G40: 13.3 | H40: =F40*G40 -> 10584.951 | I40: =H40-D40 -> 584.9513 | L40: date of purchase | N40: date of sale | X40: 5 | Y40: 41913 | Z40: 36
...

Sheet Balanced
A1: birla balanced 95 fund | L1: dsp | M1: 59558.08 | O1: 24438.61
B2: inves | C2: nav | D2: units | E2: cur.Nav | F2: cur.Value | L2: BNP | M2: 82292.98
A3: 24/05/2017 | B3: 1000 | C3: 711.77 | D3: 1.405 | E3: =MF_Summary!G6 -> 996.8 | F3: =D3*E3 -> 1400.504 | G3: =F3-B3 -> 400.504 | H3: 44244 | L3: Mirae | M3: 59952.31 | N3: 60558
A4: 16/06/2017 | B4: 10000 | C4: 740.76 | D4: 13.5 | E4: =MF_Summary!G6 -> 996.8 | F4: =D4*E4 -> 13456.8 | G4: =F4-B4 -> 3456.8 | H4: 44244 | L4: SBI | M4: 173965.45
A5: 20/07/2017 | B5: 47348.12 | C5: 755.84 | D5: 62.642 | E5: =MF_Summary!G6 -> 996.8 | F5: =D5*E5 -> 62441.546 | G5: =F5-B5 -> 15093.426 | H5: 44244 | L5: canara | M5: 71119.8
A6: 28/07/2017 | B6: 5000 | C6: 762.06 | D6: 6.561 | E6: =MF_Summary!G6 -> 996.8 | F6: =D6*E6 -> 6540.0048 | G6: =F6-B6 -> 1540.0048 | H6: 44244
A7: 03/08/2017 | B7: 10454.28 | C7: 763.31 | D7: 13.696 | E7: =MF_Summary!G6 -> 996.8 | F7: =D7*E7 -> 13652.173 | G7: =F7-B7 -> 3197.8928 | H7: 44244 | L7: 6233000
A8: 03/08/2017 | B8: 20000 | C8: 763.31 | D8: 26.202 | E8: =MF_Summary!G6 -> 996.8 | F8: =D8*E8 -> 26118.154 | G8: =F8-B8 -> 6118.1536 | H8: 44244 | I8: 2390921 | J8: 1500000 | K8: 1370000 | L8: 4145909 | M8: =SUM(M1:M6) -> 446888.62 | N8: 650000 | O8: 680000
A9: 18/08/2017 | B9: 1143.39 | C9: 760.29 | D9: 1.504 | E9: =MF_Summary!G6 -> 996.8 | F9: =D9*E9 -> 1499.1872 | G9: =F9-B9 -> 355.7972 | H9: 44244
A10: 04/09/2017 | B10: 10410.92 | C10: 769.53 | D10: 13.529 | E10: =MF_Summary!G6 -> 996.8 | F10: =D10*E10 -> 13485.707 | G10: =F10-B10 -> 3074.7872 | H10: 44244
A11: 21/09/2017 | B11: 11556.43 | C11: 783.29 | D11: 14.754 | E11: =MF_Summary!G6 -> 996.8 | F11: =D11*E11 -> 14706.787 | G11: =F11-B11 -> 3150.3572 | H11: 44244
A12: 02/02/2018 | B12: 10000 | C12: 795.35 | D12: 12.573 | E12: =MF_Summary!G6 -> 996.8 | F12: =D12*E12 -> 12532.766 | G12: =F12-B12 -> 2532.7664 | H12: 44244 | I12: ICICI Prudential Equity Arbitrage Fund | T12: 3961000
A13: 05/02/2018 | B13: 5000 | C13: 791.24 | D13: 6.319 | E13: =MF_Summary!G6 -> 996.8 | F13: =D13*E13 -> 6298.7792 | G13: =F13-B13 -> 1298.7792 | H13: 44244 | J13: inves | K13: nav | L13: units | M13: cur.Nav | N13: cur.Value | T13: =SUM(N23,L36) -> 660837.86
C14: =AVERAGE(C3:C13) -> 763.34091 | I14: 43776 | J14: 140000 | K14: 26.3479 | L14: 5313.516 | M14: 27.6692 | N14: =L14*M14 -> 147020.74 | T14: 1370000
B15: =SUM(B3:B13) -> 131913.14 | D15: =SUM(D3:D13) -> 172.685 | F15: =SUM(F3:F13) -> 172132.41 | G15: =F15-B15 -> 40219.268 | I15: 43782 | J15: 100000 | K15: 26.3746 | L15: 3791.527 | M15: 27.6692 | N15: =L15*M15 -> 104908.52 | T15: 1400000
I16: 43783 | J16: 100000 | K16: 26.3683 | L16: 3792.433 | M16: 27.6692 | N16: =L16*M16 -> 104933.59 | T16: 200000
A17: Axis equity hybrid | I17: 43784 | J17: 150000 | K17: 26.3593 | L17: 5690.591 | M17: 27.6692 | N17: =L17*M17 -> 157454.1 | T17: 2459566
B18: inves | C18: nav | D18: units | E18: cur.Nav | F18: cur.Value | I18: 43798 | J18: 110000 | K18: 26.4225 | L18: 4163.119 | M18: 27.6692 | N18: =L18*M18 -> 115190.17
A19: 43878 | B19: 50000 | C19: 11.77 | D19: 4248.088 | E19: 13.48 | F19: =E19*D19 -> 57264.226 | G19: =F19-B19 -> 7264.2262 | H19: 44253 | I19: 43822 | J19: 10000 | K19: 26.4955 | L19: 377.423 | M19: 27.6692 | N19: =L19*M19 -> 10442.992 | T19: =SUM(T12:T17) -> 10051404
A20: 43885 | B20: 10000 | C20: 11.64 | D20: 859.107 | E20: 13.48 | F20: =E20*D20 -> 11580.762 | G20: =F20-B20 -> 1580.7624 | H20: 44253 | I20: 43823 | J20: 10000 | K20: 26.487 | L20: 377.544 | M20: 27.6692 | N20: =L20*M20 -> 10446.34
I21: 43825 | J21: 10000 | K21: 26.4995 | L21: 377.366 | M21: 27.6692 | N21: =L21*M21 -> 10441.415
A22: BNP paribas balanced fund
B23: inves | C23: nav | D23: units | E23: cur.Nav | F23: cur.Value | H23: redemption dt | J23: =SUM(J14:J21) -> 630000 | N23: =SUM(N14:N21) -> 660837.86
A24: 42909 | B24: 5000 | C24: 10.3508 | D24: 483.054 | E24: 12.507 | F24: =D24*E24 -> 6041.5564 | G24: =F24-B24 -> 1041.5564 | H24: 43984
A25: 42929 | B25: 29000 | C25: 10.5898 | D25: 2738.484 | E25: 12.507 | F25: =D25*E25 -> 34250.219 | G25: =F25-B25 -> 5250.2194 | H25: 43984
A26: 42958 | B26: 5241 | C26: 10.4175 | D26: 503.1 | E26: 12.507 | F26: =D26*E26 -> 6292.2717 | G26: =F26-B26 -> 1051.2717 | H26: 43984 | J26: =SUM(F24:F29) -> 82293.796
A27: 42965 | B27: 5000 | C27: 10.5296 | D27: 474.852 | E27: 12.507 | F27: =D27*E27 -> 5938.974 | G27: =F27-B27 -> 938.97396 | H27: 43984
A28: 43004 | B28: 4681.75 | C28: 10.5715 | D28: 442.865 | E28: 12.507 | F28: =D28*E28 -> 5538.9126 | G28: =F28-B28 -> 857.16255 | H28: 43984 | O28: =SUM(N23,O38) -> 976659.36
A29: 43031 | B29: 20963.75 | C29: 10.8202 | D29: 1937.464 | E29: 12.507 | F29: =D29*E29 -> 24231.862 | G29: =F29-B29 -> 3268.1122 | H29: 43984 | O29: 680000
A30: 43874 | B30: 100000 | C30: 14.1393 | D30: 7072.486 | E30: 16.8471 | F30: =E30*D30 -> 119150.88 | G30: =F30-B30 -> 19150.879 | H30: 44253
A33: Canara Robeco Balance
B34: inves | C34: nav | D34: units | E34: cur.Nav | F34: cur.Value | H34: redemption dt
A35: 42905 | B35: 5000 | C35: 141.94 | D35: 35.226 | E35: 167.44 | F35: =D35*E35 -> 5898.2414 | G35: =F35-B35 -> 898.24144 | H35: 43984
A36: 42944 | B36: 5000 | C36: 145.27 | D36: 34.419 | E36: 167.44 | F36: =D36*E36 -> 5763.1174 | G36: =F36-B36 -> 763.11736 | H36: 43984
A37: 42950 | B37: 10000 | C37: 145.62 | D37: 68.672 | E37: 167.44 | F37: =D37*E37 -> 11498.44 | G37: =F37-B37 -> 1498.4397 | H37: 43984
A38: 42965 | B38: 5000 | C38: 144.95 | D38: 34.495 | E38: 167.44 | F38: =D38*E38 -> 5775.8428 | G38: =F38-B38 -> 775.8428 | H38: 43984 | O38: =SUM(J26,J40,J63) -> 315821.49
A39: 42982 | B39: 5000 | C39: 146.13 | D39: 34.216 | E39: 167.44 | F39: =D39*E39 -> 5729.127 | G39: =F39-B39 -> 729.12704 | H39: 43984
A40: 42999 | B40: 5000 | C40: 148.37 | D40: 33.7 | E40: 167.44 | F40: =D40*E40 -> 5642.728 | G40: =F40-B40 -> 642.728 | H40: 43984 | J40: =SUM(F35:F49) -> 173968.99
A41: 43000 | B41: 5000 | C41: 146.34 | D41: 34.167 | E41: 167.44 | F41: =D41*E41 -> 5720.9225 | G41: =F41-B41 -> 720.92248 | H41: 43984
A42: 43003 | B42: 5000 | C42: 145.19 | D42: 34.438 | E42: 167.44 | F42: =D42*E42 -> 5766.2987 | G42: =F42-B42 -> 766.29872 | H42: 43984
...

Sheet Midcap
A1: HDFC mid-cap oppertunities direct fund | K1: Sundaram Select mid-cap
B2: inves | C2: nav | D2: units | E2: cur.Nav | F2: cur.Value | L2: Invest | M2: nav | N2: units | O2: cur.Nav | P2: cur.Value
A3: 42999 | B3: 10000 | C3: 56.989 | D3: 172.472 | E3: 59.282 | F3: =D3*E3 -> 10224.485 | G3: =F3-B3 -> 224.4851 | H3: =D3 -> 172.472 | K3: 43039 | L3: 24886.99 | M3: 520.2144 | N3: 47.84 | O3: 475.0881 | P3: =N3*O3 -> 22728.215
A4: 43000 | B4: 5000 | C4: 55.677 | D4: 89.804 | E4: 59.282 | F4: =D4*E4 -> 5323.7607 | G4: =F4-B4 -> 323.76073 | H4: =D3+D4 -> 262.276 | K4: 43066 | L4: 2000 | M4: 538.77 | N4: 3.712 | O4: 475.0881 | P4: =N4*O4 -> 1763.527
A5: 43003 | B5: 5000 | C5: 55.086 | D5: 90.767 | E5: 59.282 | F5: =D5*E5 -> 5380.8493 | G5: =F5-B5 -> 380.84929 | K5: 43069 | L5: 5000 | M5: 538.0955 | N5: 9.292 | O5: 475.0881 | P5: =N5*O5 -> 4414.5186
A6: 43048 | B6: 5000 | C6: 59.276 | D6: 84.351 | E6: 59.282 | F6: =D6*E6 -> 5000.496 | G6: =F6-B6 -> 0.495982 | K6: 43096 | L6: 64428 | M6: 557.3003 | N6: 115.607 | O6: 475.0881 | P6: =N6*O6 -> 54923.51
A7: 43052 | B7: 5000 | C7: 59.097 | D7: 84.607 | E7: 59.282 | F7: =D7*E7 -> 5015.6722 | G7: =F7-B7 -> 15.672174 | K7: 43125 | L7: 10000 | M7: 553.9582 | N7: 18.052 | O7: 475.0881 | P7: =N7*O7 -> 8576.2904
A8: 43054 | B8: 2000 | C8: 58.314 | D8: 34.297 | E8: 59.282 | F8: =D8*E8 -> 2033.1948 | G8: =F8-B8 -> 33.194754 | K8: 43133 | L8: 10000 | M8: 525.7504 | N8: 19.02 | O8: 475.0881 | P8: =N8*O8 -> 9036.1757
A9: 43066 | B9: 2000 | C9: 60.281 | D9: 33.178 | E9: 59.282 | F9: =D9*E9 -> 1966.8582 | G9: =F9-B9 -> -33.141804 | K9: 43153 | L9: 3000 | M9: 519.5599 | N9: 5.774 | O9: 475.0881 | P9: =N9*O9 -> 2743.1587
A10: 43069 | B10: 10000 | C10: 59.875 | D10: 167.015 | E10: 59.282 | F10: =D10*E10 -> 9900.9832 | G10: =F10-B10 -> -99.01677 | K10: 43164 | L10: 5000 | M10: 524.7461 | N10: 9.528 | O10: 475.0881 | P10: =N10*O10 -> 4526.6394
A11: 43075 | B11: 2000 | C11: 58.935 | D11: 33.936 | E11: 59.282 | F11: =D11*E11 -> 2011.794 | G11: =F11-B11 -> 11.793952 | K11: 43182 | L11: 5000 | M11: 503.2336 | N11: 9.9357 | O11: 475.0881 | P11: =N11*O11 -> 4720.3328
A12: 43081 | B12: 5000 | C12: 59.753 | D12: 83.678 | E12: 59.282 | F12: =D12*E12 -> 4960.5992 | G12: =F12-B12 -> -39.400804 | K12: 43224 | L12: 10000 | M12: 538.9554 | N12: 19.468 | O12: 475.0881 | P12: =N12*O12 -> 9249.0151
A13: 43110 | B13: 10000 | C13: 63.748 | D13: 156.868 | E13: 59.282 | F13: =D13*E13 -> 9299.4488 | G13: =F13-B13 -> -700.55122 | K13: 43256 | L13: 5000 | M13: 508.8307 | N13: 9.826 | O13: 475.0881 | P13: =N13*O13 -> 4668.2157
A14: 43125 | B14: 10000 | C14: 62.716 | D14: 159.449 | E14: 59.282 | F14: =D14*E14 -> 9452.4556 | G14: =F14-B14 -> -547.54438 | K14: 43278 | L14: 10000 | M14: 497.2493 | N14: 20.111 | O14: 475.0881 | P14: =N14*O14 -> 9554.4968
A15: 43130 | B15: 5000 | C15: 61.687 | D15: 81.054 | E15: 59.282 | F15: =D15*E15 -> 4805.0432 | G15: =F15-B15 -> -194.95677
A16: 43133 | B16: 10000 | C16: 59.106 | D16: 169.188 | E16: 59.282 | F16: =D16*E16 -> 10029.803 | G16: =F16-B16 -> 29.803016 | M16: =SUM(M3:M15) -> 6326.6638
A17: 43136 | B17: 10000 | C17: 58.9 | D17: 169.779 | E17: 59.282 | F17: =D17*E17 -> 10064.839 | G17: =F17-B17 -> 64.838678 | L17: =SUM(L3:L14) -> 154314.99 | N17: =SUM(N3:N14) -> 288.1657 | P17: =SUM(P3:P14) -> 136904.09
A18: 43139 | B18: 10000 | C18: 59.397 | D18: 168.359 | E18: 59.282 | F18: =D18*E18 -> 9980.6582 | G18: =F18-B18 -> -19.341762
A19: 43151 | B19: 5000 | C19: 58.618 | D19: 85.298 | E19: 59.282 | F19: =D19*E19 -> 5056.636 | G19: =F19-B19 -> 56.636036
A20: 43153 | B20: 3000 | C20: 58.562 | D20: 51.228 | E20: 59.282 | F20: =D20*E20 -> 3036.8983 | G20: =F20-B20 -> 36.898296
A21: 43164 | B21: 5000 | C21: 59.025 | D21: 84.71 | E21: 59.282 | F21: =D21*E21 -> 5021.7782 | G21: =F21-B21 -> 21.77822
A22: 43182 | B22: 10000 | C22: 57.068 | D22: 175.23 | E22: 59.282 | F22: =D22*E22 -> 10387.985 | G22: =F22-B22 -> 387.98486
A23: 43256 | B23: 5000 | C23: 57.753 | D23: 86.576 | E23: 59.282 | F23: =D23*E23 -> 5132.3984 | G23: =F23-B23 -> 132.39843
A24: 43279 | B24: 10000 | C24: 56.498 | D24: 176.997 | E24: 59.282 | F24: =D24*E24 -> 10492.736 | G24: =F24-B24 -> 492.73615
C26: =AVERAGE(C3:C24) -> 58.9255
A30: Canara Robeco Emerging Equities | K30: Franklin India Prima Fund
C31: nav | D31: units | E31: cur.Nav | F31: cur.Value | M31: nav | N31: units | O31: cur.Nav | P31: cur.Value
A32: 43003 | B32: 5000 | C32: 91.08 | D32: 54.897 | E32: 97.79 | F32: =D32*E32 -> 5368.3776 | K32: 43005 | L32: 355.7107 | M32: 941.0336 | N32: 0.378 | O32: 1038.0962 | P32: =N32*O32 -> 392.40036 | Q32: =P32-L32 -> 36.689664
A33: 43046 | B33: 5000 | C33: 96.67 | D33: 51.722 | E33: 97.79 | F33: =D33*E33 -> 5057.8944 | K33: 43046 | L33: 5000 | M33: 1001.5664 | N33: 4.992 | O33: 1038.0962 | P33: =N33*O33 -> 5182.1762 | Q33: =P33-L33 -> 182.17623
A34: 43052 | B34: 5000 | C34: 95.63 | D34: 52.285 | E34: 97.79 | F34: =D34*E34 -> 5112.9501 | K34: 43048 | L34: 2000 | M34: 1003.763 | N34: 1.993 | O34: 1038.0962 | P34: =N34*O34 -> 2068.9257 | Q34: =P34-L34 -> 68.925727
A35: 43054 | B35: 2000 | C35: 94.94 | D35: 21.066 | E35: 97.79 | F35: =D35*E35 -> 2060.0441 | K35: 43052 | L35: 5000 | M35: 1003.9989 | N35: 4.98 | O35: 1038.0962 | P35: =N35*O35 -> 5169.7191 | Q35: =P35-L35 -> 169.71908
A36: 43066 | B36: 3000 | C36: 98.69 | D36: 30.398 | E36: 97.79 | F36: =D36*E36 -> 2972.6204 | K36: 43054 | L36: 2000 | M36: 994.8978 | N36: 2.01 | O36: 1038.0962 | P36: =N36*O36 -> 2086.5734 | Q36: =P36-L36 -> 86.573362
A37: 43069 | B37: 10000 | C37: 98.73 | D37: 101.286 | E37: 97.79 | F37: =D37*E37 -> 9904.7579 | K37: 43066 | L37: 5000 | M37: 1028.183 | N37: 4.863 | O37: 1038.0962 | P37: =N37*O37 -> 5048.2618 | Q37: =P37-L37 -> 48.261821
A38: 43075 | B38: 2000 | C38: 96.72 | D38: 20.678 | E38: 97.79 | F38: =D38*E38 -> 2022.1016 | K38: 43069 | L38: 10000 | M38: 1030.3098 | N38: 9.706 | O38: 1038.0962 | P38: =N38*O38 -> 10075.762 | Q38: =P38-L38 -> 75.761717
A39: 43125 | B39: 10000 | C39: 102.85 | D39: 97.229 | E39: 97.79 | F39: =D39*E39 -> 9508.0239 | K39: 43075 | L39: 2000 | M39: 1013.7329 | N39: 1.973 | O39: 1038.0962 | P39: =N39*O39 -> 2048.1638 | Q39: =P39-L39 -> 48.163803
A40: 43133 | B40: 10000 | C40: 98.43 | D40: 101.595 | E40: 97.79 | F40: =D40*E40 -> 9934.9751 | K40: 43081 | L40: 5000 | M40: 1023.3169 | N40: 4.886 | O40: 1038.0962 | P40: =N40*O40 -> 5072.138 | Q40: =P40-L40 -> 72.138033
A41: 43136 | B41: 10000 | C41: 98.03 | D41: 102.01 | E41: 97.79 | F41: =D41*E41 -> 9975.5579 | K41: 43110 | L41: 10000 | M41: 1091.6542 | N41: 9.16 | O41: 1038.0962 | P41: =N41*O41 -> 9508.9612 | Q41: =P41-L41 -> -491.03881
A42: 43153 | B42: 3000 | C42: 97.45 | D42: 30.785 | E42: 97.79 | F42: =D42*E42 -> 3010.4651 | K42: 43125 | L42: 10000 | M42: 1079.4029 | N42: 9.264 | O42: 1038.0962 | P42: =N42*O42 -> 9616.9232 | Q42: =P42-L42 -> -383.0768
C43: =AVERAGE(C32:C42) -> 97.201818 | D43: =SUM(D32:D42) -> 663.951 | K43: 43130 | L43: 5000 | M43: 1067.2102 | N43: 4.685 | O43: 1038.0962 | P43: =N43*O43 -> 4863.4807 | Q43: =P43-L43 -> -136.5193
B44: =SUM(B32:B42) -> 65000 | K44: 43133 | L44: 10000 | M44: 1036.682 | N44: 9.646 | O44: 1038.0962 | P44: =N44*O44 -> 10013.476 | Q44: =P44-L44 -> 13.475945
...

Sheet Largecap
A1: Mirae Asset India Equity Fund | I1: Quantum Long Term Equity | Q1: Aditya birla frontline equity fund
C2: nav | D2: units | E2: cur.Nav | F2: cur.Value | K2: nav | L2: units | M2: cur.Nav | N2: cur.Value | S2: nav | T2: units | U2: cur.Nav | V2: cur.Value
A3: 42965 | B3: 5000 | C3: 45.815 | D3: 109.135 | E3: 54.615 | F3: =D3*E3 -> 5960.408 | G3: =F3-B3 -> 960.40803 | I3: 42897 | J3: 1000 | K3: 53.73 | L3: 18.612 | M3: 53.43 | N3: =L3*M3 -> 994.43916 | Q3: 14/11/2017 | R3: 66775.47 | S3: 224.39 | T3: 297.588 | U3: 237.62 | V3: =T3*U3 -> 70712.861
A4: 42999 | B4: 10000 | C4: 47.745 | D4: 209.446 | E4: 54.615 | F4: =D4*E4 -> 11438.893 | G4: =F4-B4 -> 1438.8933 | I4: 42958 | J4: 5000 | K4: 52.62 | L4: 95.021 | M4: 53.43 | N4: =L4*M4 -> 5076.972 | Q4: 30/11/2017 | R4: 10000 | S4: 225.24 | T4: 44.397 | U4: 237.62 | V4: =T4*U4 -> 10549.615
A5: 43000 | B5: 10000 | C5: 46.712 | D5: 214.078 | E5: 54.615 | F5: =D5*E5 -> 11691.87 | G5: =F5-B5 -> 1691.87 | I5: 43052 | J5: 5000 | K5: 52.56 | L5: 95.129 | M5: 53.43 | N5: =L5*M5 -> 5082.7425 | Q5: 42898 | R5: 3000 | S5: 221.02 | T5: 13.573 | U5: 237.62 | V5: =T5*U5 -> 3225.2163
A6: 43003 | B6: 5000 | C6: 46.155 | D6: 108.331 | E6: 54.615 | F6: =D6*E6 -> 5916.4976 | G6: =F6-B6 -> 916.49757 | I6: 43054 | J6: 5000 | K6: 52.11 | L6: 95.951 | M6: 53.43 | N6: =L6*M6 -> 5126.6619 | Q6: 43081 | R6: 5000 | S6: 225.65 | T6: 22.158 | U6: 237.62 | V6: =T6*U6 -> 5265.184
A7: 43047 | B7: 5000 | C7: 48.656 | D7: 102.762 | E7: 54.615 | F7: =D7*E7 -> 5612.3466 | G7: =F7-B7 -> 612.34663 | I7: 43066 | J7: 5000 | K7: 53.34 | L7: 93.738 | M7: 53.43 | N7: =L7*M7 -> 5008.4213 | Q7: 43374 | R7: 10000 | S7: 235.12 | T7: 42.531 | U7: 237.62 | V7: =T7*U7 -> 10106.216
A8: 43054 | B8: 5000 | C8: 47.968 | D8: 104.236 | E8: 54.615 | F8: =D8*E8 -> 5692.8491 | G8: =F8-B8 -> 692.84914 | I8: 43073 | J8: 10000 | K8: 52.21 | L8: 191.534 | M8: 53.43 | N8: =L8*M8 -> 10233.662 | Q8: 25/01/2018 | R8: 10000 | S8: 239.29 | T8: 41.79 | U8: 237.62 | V8: =T8*U8 -> 9930.1398
A9: 43066 | B9: 5000 | C9: 49.541 | D9: 7464764 | E9: 54.615 | F9: =D9*E9 -> 4.0768809e+08 | G9: =F9-B9 -> 4.0768309e+08 | I9: 43075 | J9: 3000 | K9: 51.62 | L9: 58.117 | M9: 53.43 | N9: =L9*M9 -> 3105.1913 | Q9: 43133 | R9: 10000 | S9: 231.43 | T9: 43.21 | U9: 237.62 | V9: =T9*U9 -> 10267.56
A10: 43073 | B10: 10000 | C10: 48.295 | D10: 767585 | E10: 54.615 | F10: =D10*E10 -> 41921655 | G10: =F10-B10 -> 41911655 | I10: 43081 | J10: 10000 | K10: 52.37 | L10: 190.949 | M10: 53.43 | N10: =L10*M10 -> 10202.405 | Q10: 43222 | R10: 10000 | S10: 230.24 | T10: 43.433 | U10: 237.62 | V10: =T10*U10 -> 10320.549
A11: 43075 | B11: 2000 | C11: 47.859 | D11: 41.789 | E11: 54.615 | F11: =D11*E11 -> 2282.3062 | G11: =F11-B11 -> 282.30624 | I11: 43110 | J11: 10000 | K11: 54.5 | L11: 183.486 | M11: 53.43 | N11: =L11*M11 -> 9803.657 | Q11: 43153 | R11: 3000 | S11: 223.47 | T11: 13.425 | U11: 237.62 | V11: =T11*U11 -> 3190.0485
A12: 43081 | B12: 10000 | C12: 48.975 | D12: 204.186 | E12: 54.615 | F12: =D12*E12 -> 11151.618 | G12: =F12-B12 -> 1151.6184 | I12: 43129 | J12: 10000 | K12: 55.83 | L12: 179.115 | M12: 53.43 | N12: =L12*M12 -> 9570.1145 | Q12: 43162 | R12: 5000 | S12: 223.27 | T12: 22.394 | U12: 237.62 | V12: =T12*U12 -> 5321.2623
A13: 43110 | B13: 10000 | C13: 51.021 | D13: 195.998 | E13: 54.615 | F13: =D13*E13 -> 10704.431 | G13: =F13-B13 -> 704.43077 | I13: 43130 | J13: 5000 | K13: 55.59 | L13: 89.944 | M13: 53.43 | N13: =L13*M13 -> 4805.7079 | Q13: 43167 | R13: 10000 | S13: 220.81 | T13: 45.287 | U13: 237.62 | V13: =T13*U13 -> 10761.097
A14: 43129 | B14: 10000 | C14: 52.433 | D14: 190.72 | E14: 54.615 | F14: =D14*E14 -> 10416.173 | G14: =F14-B14 -> 416.1728 | I14: 43136 | J14: 20000 | K14: 53.56 | L14: 373.413 | M14: 53.43 | N14: =L14*M14 -> 19951.457 | T14: =SUM(T3:T13) -> 629.786
A15: 43130 | B15: 5000 | C15: 52.072 | D15: 96.021 | E15: 54.615 | F15: =D15*E15 -> 5244.1869 | G15: =F15-B15 -> 244.18692 | I15: 43136 | J15: 10000 | K15: 53.56 | L15: 186.706 | M15: 53.43 | N15: =L15*M15 -> 9975.7016
A16: 43136 | B16: 10000 | C16: 49.738 | D16: 201.054 | E16: 54.615 | F16: =D16*E16 -> 10980.564 | G16: =F16-B16 -> 980.56421 | I16: 43153 | J16: 3000 | K16: 52.47 | L16: 57.176 | M16: 53.43 | N16: =L16*M16 -> 3054.9137
A17: 43136 | B17: 10000 | C17: 49.738 | D17: 201.054 | E17: 54.615 | F17: =D17*E17 -> 10980.564 | G17: =F17-B17 -> 980.56421 | I17: 43158 | J17: 10000 | K17: 53.09 | L17: 188.3594 | M17: 53.43 | N17: =L17*M17 -> 10064.043 | R17: =R10+R13 -> 20000 | S17: =(S10+S13)/2 -> 225.525 | T17: =T10+T13 -> 88.72
A18: 43153 | B18: 3000 | C18: 48.331 | D18: 62.072 | E18: 54.615 | F18: =D18*E18 -> 3390.0623 | G18: =F18-B18 -> 390.06228 | I18: 43159 | J18: 5000 | K18: 52.98 | L18: 94.37 | M18: 53.43 | N18: =L18*M18 -> 5042.1891 | S18: =S17*T17 -> 20008.578
A19: 43162 | B19: 5000 | C19: 48.34 | D19: 103.434 | E19: 54.615 | F19: =D19*E19 -> 5649.0479 | G19: =F19-B19 -> 649.04791 | I19: 43162 | J19: 5000 | K19: 52.25 | L19: 95.694 | M19: 53.43 | N19: =L19*M19 -> 5112.9304
A20: 43182 | B20: 5000 | C20: 46.956 | D20: 106.483 | E20: 54.615 | F20: =D20*E20 -> 5815.569 | G20: =F20-B20 -> 815.56905 | I20: 43167 | J20: 10000 | K20: 51.71 | L20: 193.386 | M20: 53.43 | N20: =L20*M20 -> 10332.614
A21: 43241 | B21: 5000 | C21: 47.91 | D21: 104.362 | E21: 54.615 | F21: =D21*E21 -> 5699.7306 | G21: =F21-B21 -> 699.73063 | I21: 43178 | J21: 10000 | K21: 50.99 | L21: 196.117 | M21: 53.43 | N21: =L21*M21 -> 10478.531
A22: 43256 | B22: 5000 | C22: 48.443 | D22: 103.214 | E22: 54.615 | F22: =D22*E22 -> 5637.0326 | G22: =F22-B22 -> 637.03261 | I22: 43182 | J22: 5000 | K22: 50.74 | L22: 98.542 | M22: 53.43 | N22: =L22*M22 -> 5265.0991
I23: 43237 | J23: 10000 | K23: 52.62 | L23: 190.042 | M23: 53.43 | N23: =L23*M23 -> 10153.944
I24: 43240 | J24: 5000 | K24: 51.67 | L24: 96.768 | M24: 53.43 | N24: =L24*M24 -> 5170.3142
I25: 43241 | J25: 5000 | K25: 51.67 | L25: 96.768 | M25: 53.43 | N25: =L25*M25 -> 5170.3142
I26: 43256 | J26: 5000 | K26: 51.86 | L26: 96.413 | M26: 53.43 | N26: =L26*M26 -> 5151.3466
I27: 43279 | J27: 5000 | K27: 51.64 | L27: 96.824 | M27: 53.43 | N27: =L27*M27 -> 5173.3063
B28: =SUM(B3:B27) -> 135000 | C28: =AVERAGE(C3:C27) -> 48.63515 | F28: =SUM(F3:F27) -> 4.49744e+08
K29: =AVERAGE(K3:K27) -> 52.6916
J30: =SUM(J3:J27) -> 177000 | N30: =SUM(N3:N27) -> 179106.68
A34: Franklin india bluechip fund
C35: nav | D35: units | E35: cur.Nav | F35: cur.Value
A36: 43237 | B36: 5000 | C36: 465.2674 | D36: 10.747 | E36: 472.5081 | F36: =D36*E36 -> 5078.0446
A37: 43238 | B37: 5000 | C37: 460.6376 | D37: 10.855 | E37: 472.5081 | F37: =D37*E37 -> 5129.0754
A38: 43241 | B38: 5000 | C38: 456.3792 | D38: 10.956 | E38: 472.5081 | F38: =D38*E38 -> 5176.7987

Sheet Diversified
A1: Motilal Oswal Most Focused multicap 35 Fund | L1: L&T India Special Situations Fund
C2: nav | D2: units | E2: cur.Nav | F2: cur.Value | N2: nav | O2: units | P2: cur.Nav | Q2: cur.Value
A3: 42936 | B3: 119023 | C3: 25.5291 | D3: 4662.271 | E3: 27.8889 | F3: =D3*E3 -> 130025.61 | L3: 42940 | M3: 72901.15 | N3: 48.142 | O3: 1514.295 | P3: 51.69 | Q3: =O3*P3 -> 78273.909
A4: 42940 | B4: 99559.86 | C4: 25.4474 | D4: 3912.378 | E4: 27.8889 | F4: =D4*E4 -> 109111.92 | L4: 42958 | M4: 12226.96 | N4: 46.175 | O4: 264.796 | P4: 51.69 | Q4: =O4*P4 -> 13687.305
A5: 42958 | B5: 4312.43 | C5: 25.6902 | D5: 167.863 | E5: 27.8889 | F5: =D5*E5 -> 4681.5144 | L5: 42999 | M5: 12942.69 | N5: 49.592 | O5: 260.983 | P5: 51.69 | Q5: =O5*P5 -> 13490.211
A6: 42999 | B6: 4502.58 | C6: 27.3059 | D6: 164.894 | E6: 27.8889 | F6: =D6*E6 -> 4598.7123 | L6: 43019 | M6: 12234.24 | N6: 48.848 | O6: 250.455 | P6: 51.69 | Q6: =O6*P6 -> 12946.019
A7: 43031 | B7: 17943.77 | C7: 26.9007 | D7: 667.037 | E7: 27.8889 | F7: =D7*E7 -> 18602.928 | L7: 43031 | M7: 38429.78 | N7: 50.03 | O7: 768.135 | P7: 51.69 | Q7: =O7*P7 -> 39704.898
A8: 43069 | B8: 10000 | C8: 27.14 | D8: 368.46 | E8: 27.8889 | F8: =D8*E8 -> 10275.944 | L8: 43069 | M8: 10000 | N8: 51.31 | O8: 194.894 | P8: 51.69 | Q8: =O8*P8 -> 10074.071
A9: 43081 | B9: 5000 | C9: 27.4795 | D9: 181.954 | E9: 27.8889 | F9: =D9*E9 -> 5074.4969 | L9: 43081 | M9: 4000 | N9: 51.075 | O9: 78.316 | P9: 51.69 | Q9: =O9*P9 -> 4048.154
A10: 43130 | B10: 5000 | C10: 28.3192 | D10: 176.559 | E10: 27.8889 | F10: =D10*E10 -> 4924.0363 | L10: 43125 | M10: 10000 | N10: 54.466 | O10: 183.601 | P10: 51.69 | Q10: =O10*P10 -> 9490.3357
C11: =AVERAGE(C3:C10) -> 26.7265 | L11: 43130 | M11: 5000 | N11: 53.779 | O11: 92.973 | P11: 51.69 | Q11: =O11*P11 -> 4805.7744
L12: 43133 | M12: 10000 | N12: 51.765 | O12: 193.181 | P12: 51.69 | Q12: =O12*P12 -> 9985.5259
B13: =SUM(B3:B10) -> 265341.64 | D13: =SUM(D3:D10) -> 10301.416 | F13: =SUM(F3:F10) -> 287295.16 | L13: 43136 | M13: 5000 | N13: 51.74 | O13: 96.637 | P13: 51.69 | Q13: =O13*P13 -> 4995.1665
N14: =AVERAGE(N3:N13) -> 50.629273
M15: =SUM(M3:M13) -> 192734.82 | O15: =SUM(O3:O14) -> 3898.266 | Q15: =SUM(Q3:Q13) -> 201501.37
A18: Edelweiss liquid | I18: Motilal Oswal liquid | Q18: canara robecco
A20: 45342 | C20: 190000 | I20: 45343 | K20: 190000 | Q20: 45343 | S20: 10000
A21: 45345 | C21: 200000 | I21: 45350 | K21: 200000 | Q21: 45344 | S21: 200000
A22: 45348 | C22: 200000 | I22: 45357 | K22: 200000 | Q22: 45349 | S22: 200000
A23: 45351 | C23: 200000 | I23: 45365 | K23: 200000 | Q23: 45365 | S23: 200000
A24: 45356 | C24: 200000

Sheet 2019-20
A1: Sundaram Select mid-cap | I1: Mirae Asset India Equity Fund | Q1: Quantum Long Term Equity | Y1: Aditya birla frontline equity fund
B2: Invest | C2: nav | D2: units | E2: cur.Nav | F2: cur.Value | K2: nav | L2: units | M2: cur.Nav | N2: cur.Value | S2: nav | T2: units | U2: cur.Nav | V2: cur.Value | AA2: nav | AB2: units | AC2: cur.Nav | AD2: cur.Value
A3: 43039 | B3: 24886.99 | C3: 520.2144 | D3: 47.84 | E3: 475.0881 | F3: =D3*E3 -> 22728.215 | I3: 42965 | J3: 5000 | K3: 45.815 | L3: 109.135 | M3: 54.615 | N3: =L3*M3 -> 5960.408 | O3: =N3-J3 -> 960.40803 | Q3: 42897 | R3: 1000 | S3: 53.73 | T3: 18.612 | U3: 53.43 | V3: =T3*U3 -> 994.43916 | Y3: 14/11/2017 | Z3: 66775.47 | AA3: 224.39 | AB3: 297.588 | AC3: 237.62 | AD3: =AB3*AC3 -> 70712.861
A4: 43066 | B4: 2000 | C4: 538.77 | D4: 3.712 | E4: 475.0881 | F4: =D4*E4 -> 1763.527 | I4: 42999 | J4: 10000 | K4: 47.745 | L4: 209.446 | M4: 54.615 | N4: =L4*M4 -> 11438.893 | O4: =N4-J4 -> 1438.8933 | Q4: 42958 | R4: 5000 | S4: 52.62 | T4: 95.021 | U4: 53.43 | V4: =T4*U4 -> 5076.972 | Y4: 30/11/2017 | Z4: 10000 | AA4: 225.24 | AB4: 44.397 | AC4: 237.62 | AD4: =AB4*AC4 -> 10549.615
A5: 43069 | B5: 5000 | C5: 538.0955 | D5: 9.292 | E5: 475.0881 | F5: =D5*E5 -> 4414.5186 | I5: 43000 | J5: 10000 | K5: 46.712 | L5: 214.078 | M5: 54.615 | N5: =L5*M5 -> 11691.87 | O5: =N5-J5 -> 1691.87 | Q5: 43052 | R5: 5000 | S5: 52.56 | T5: 95.129 | U5: 53.43 | V5: =T5*U5 -> 5082.7425 | Y5: 42898 | Z5: 3000 | AA5: 221.02 | AB5: 13.573 | AC5: 237.62 | AD5: =AB5*AC5 -> 3225.2163
A6: 43096 | B6: 64428 | C6: 557.3003 | D6: 115.607 | E6: 475.0881 | F6: =D6*E6 -> 54923.51 | I6: 43003 | J6: 5000 | K6: 46.155 | L6: 108.331 | M6: 54.615 | N6: =L6*M6 -> 5916.4976 | O6: =N6-J6 -> 916.49757 | Q6: 43054 | R6: 5000 | S6: 52.11 | T6: 95.951 | U6: 53.43 | V6: =T6*U6 -> 5126.6619 | Y6: 43081 | Z6: 5000 | AA6: 225.65 | AB6: 22.158 | AC6: 237.62 | AD6: =AB6*AC6 -> 5265.184
A7: 43125 | B7: 10000 | C7: 553.9582 | D7: 18.052 | E7: 475.0881 | F7: =D7*E7 -> 8576.2904 | I7: 43047 | J7: 5000 | K7: 48.656 | L7: 102.762 | M7: 54.615 | N7: =L7*M7 -> 5612.3466 | O7: =N7-J7 -> 612.34663 | Q7: 43066 | R7: 5000 | S7: 53.34 | T7: 93.738 | U7: 53.43 | V7: =T7*U7 -> 5008.4213 | Y7: 43374 | Z7: 10000 | AA7: 235.12 | AB7: 42.531 | AC7: 237.62 | AD7: =AB7*AC7 -> 10106.216
A8: 43133 | B8: 10000 | C8: 525.7504 | D8: 19.02 | E8: 475.0881 | F8: =D8*E8 -> 9036.1757 | I8: 43054 | J8: 5000 | K8: 47.968 | L8: 104.236 | M8: 54.615 | N8: =L8*M8 -> 5692.8491 | O8: =N8-J8 -> 692.84914 | Q8: 43073 | R8: 10000 | S8: 52.21 | T8: 191.534 | U8: 53.43 | V8: =T8*U8 -> 10233.662 | Y8: 25/01/2018 | Z8: 10000 | AA8: 239.29 | AB8: 41.79 | AC8: 237.62 | AD8: =AB8*AC8 -> 9930.1398
A9: 43153 | B9: 3000 | C9: 519.5599 | D9: 5.774 | E9: 475.0881 | F9: =D9*E9 -> 2743.1587 | I9: 43066 | J9: 5000 | K9: 49.541 | L9: 100.927 | M9: 54.615 | N9: =L9*M9 -> 5512.1281 | O9: =N9-J9 -> 512.12811 | Q9: 43075 | R9: 3000 | S9: 51.62 | T9: 58.117 | U9: 53.43 | V9: =T9*U9 -> 3105.1913 | Y9: 43133 | Z9: 10000 | AA9: 231.43 | AB9: 43.21 | AC9: 237.62 | AD9: =AB9*AC9 -> 10267.56
A10: 43164 | B10: 5000 | C10: 524.7461 | D10: 9.528 | E10: 475.0881 | F10: =D10*E10 -> 4526.6394 | I10: 43073 | J10: 10000 | K10: 48.295 | L10: 207.061 | M10: 54.615 | N10: =L10*M10 -> 11308.637 | O10: =N10-J10 -> 1308.6365 | Q10: 43081 | R10: 10000 | S10: 52.37 | T10: 190.949 | U10: 53.43 | V10: =T10*U10 -> 10202.405 | Y10: 43222 | Z10: 10000 | AA10: 230.24 | AB10: 43.433 | AC10: 237.62 | AD10: =AB10*AC10 -> 10320.549
A11: 43182 | B11: 5000 | C11: 503.2336 | D11: 9.9357 | E11: 475.0881 | F11: =D11*E11 -> 4720.3328 | I11: 43075 | J11: 2000 | K11: 47.859 | L11: 41.789 | M11: 54.615 | N11: =L11*M11 -> 2282.3062 | O11: =N11-J11 -> 282.30624 | Q11: 43110 | R11: 10000 | S11: 54.5 | T11: 183.486 | U11: 53.43 | V11: =T11*U11 -> 9803.657 | Y11: 43153 | Z11: 3000 | AA11: 223.47 | AB11: 13.425 | AC11: 237.62 | AD11: =AB11*AC11 -> 3190.0485
A12: 43224 | B12: 10000 | C12: 538.9554 | D12: 19.468 | E12: 475.0881 | F12: =D12*E12 -> 9249.0151 | I12: 43081 | J12: 10000 | K12: 48.975 | L12: 204.186 | M12: 54.615 | N12: =L12*M12 -> 11151.618 | O12: =N12-J12 -> 1151.6184 | Q12: 43129 | R12: 10000 | S12: 55.83 | T12: 179.115 | U12: 53.43 | V12: =T12*U12 -> 9570.1145 | Y12: 43162 | Z12: 5000 | AA12: 223.27 | AB12: 22.394 | AC12: 237.62 | AD12: =AB12*AC12 -> 5321.2623
A13: 43256 | B13: 5000 | C13: 508.8307 | D13: 9.826 | E13: 475.0881 | F13: =D13*E13 -> 4668.2157 | I13: 43110 | J13: 10000 | K13: 51.021 | L13: 195.998 | M13: 54.615 | N13: =L13*M13 -> 10704.431 | O13: =N13-J13 -> 704.43077 | Q13: 43130 | R13: 5000 | S13: 55.59 | T13: 89.944 | U13: 53.43 | V13: =T13*U13 -> 4805.7079 | Y13: 43167 | Z13: 10000 | AA13: 220.81 | AB13: 45.287 | AC13: 237.62 | AD13: =AB13*AC13 -> 10761.097
A14: 43278 | B14: 10000 | C14: 497.2493 | D14: 20.111 | E14: 475.0881 | F14: =D14*E14 -> 9554.4968 | I14: 43129 | J14: 10000 | K14: 52.433 | L14: 190.72 | M14: 54.615 | N14: =L14*M14 -> 10416.173 | O14: =N14-J14 -> 416.1728 | Q14: 43136 | R14: 20000 | S14: 53.56 | T14: 373.413 | U14: 53.43 | V14: =T14*U14 -> 19951.457 | AB14: =SUM(AB3:AB13) -> 629.786
I15: 43130 | J15: 5000 | K15: 52.072 | L15: 96.021 | M15: 54.615 | N15: =L15*M15 -> 5244.1869 | O15: =N15-J15 -> 244.18692 | Q15: 43136 | R15: 10000 | S15: 53.56 | T15: 186.706 | U15: 53.43 | V15: =T15*U15 -> 9975.7016
C16: =SUM(C3:C15) -> 6326.6638 | I16: 43136 | J16: 10000 | K16: 49.738 | L16: 201.054 | M16: 54.615 | N16: =L16*M16 -> 10980.564 | O16: =N16-J16 -> 980.56421 | Q16: 43153 | R16: 3000 | S16: 52.47 | T16: 57.176 | U16: 53.43 | V16: =T16*U16 -> 3054.9137
B17: =SUM(B3:B14) -> 154314.99 | D17: =SUM(D3:D14) -> 288.1657 | F17: =SUM(F3:F14) -> 136904.09 | I17: 43136 | J17: 10000 | K17: 49.738 | L17: 201.054 | M17: 54.615 | N17: =L17*M17 -> 10980.564 | O17: =N17-J17 -> 980.56421 | Q17: 43158 | R17: 10000 | S17: 53.09 | T17: 188.3594 | U17: 53.43 | V17: =T17*U17 -> 10064.043 | Z17: =Z10+Z13 -> 20000 | AA17: =(AA10+AA13)/2 -> 225.525 | AB17: =AB10+AB13 -> 88.72
I18: 43153 | J18: 3000 | K18: 48.331 | L18: 62.072 | M18: 54.615 | N18: =L18*M18 -> 3390.0623 | O18: =N18-J18 -> 390.06228 | Q18: 43159 | R18: 5000 | S18: 52.98 | T18: 94.37 | U18: 53.43 | V18: =T18*U18 -> 5042.1891 | AA18: =AA17*AB17 -> 20008.578
A19: Motilal Oswal Most Focused multicap 35 Fund | I19: 43162 | J19: 5000 | K19: 48.34 | L19: 103.434 | M19: 54.615 | N19: =L19*M19 -> 5649.0479 | O19: =N19-J19 -> 649.04791 | Q19: 43162 | R19: 5000 | S19: 52.25 | T19: 95.694 | U19: 53.43 | V19: =T19*U19 -> 5112.9304
B20: Invest | C20: nav | D20: units | E20: cur.Nav | F20: cur.Value | I20: 43182 | J20: 5000 | K20: 46.956 | L20: 106.483 | M20: 54.615 | N20: =L20*M20 -> 5815.569 | O20: =N20-J20 -> 815.56905 | Q20: 43167 | R20: 10000 | S20: 51.71 | T20: 193.386 | U20: 53.43 | V20: =T20*U20 -> 10332.614
A21: 42936 | B21: 119023 | C21: 25.5291 | D21: 4662.271 | E21: 27.8889 | F21: =D21*E21 -> 130025.61 | I21: 43241 | J21: 5000 | K21: 47.91 | L21: 104.362 | M21: 54.615 | N21: =L21*M21 -> 5699.7306 | O21: =N21-J21 -> 699.73063 | Q21: 43178 | R21: 10000 | S21: 50.99 | T21: 196.117 | U21: 53.43 | V21: =T21*U21 -> 10478.531
A22: 42940 | B22: 99559.86 | C22: 25.4474 | D22: 3912.378 | E22: 27.8889 | F22: =D22*E22 -> 109111.92 | I22: 43256 | J22: 5000 | K22: 48.443 | L22: 103.214 | M22: 54.615 | N22: =L22*M22 -> 5637.0326 | O22: =N22-J22 -> 637.03261 | Q22: 43182 | R22: 5000 | S22: 50.74 | T22: 98.542 | U22: 53.43 | V22: =T22*U22 -> 5265.0991
A23: 42958 | B23: 4312.43 | C23: 25.6902 | D23: 167.863 | E23: 27.8889 | F23: =D23*E23 -> 4681.5144 | Q23: 43237 | R23: 10000 | S23: 52.62 | T23: 190.042 | U23: 53.43 | V23: =T23*U23 -> 10153.944
A24: 42999 | B24: 4502.58 | C24: 27.3059 | D24: 164.894 | E24: 27.8889 | F24: =D24*E24 -> 4598.7123 | Q24: 43240 | R24: 5000 | S24: 51.67 | T24: 96.768 | U24: 53.43 | V24: =T24*U24 -> 5170.3142
A25: 43031 | B25: 17943.77 | C25: 26.9007 | D25: 667.037 | E25: 27.8889 | F25: =D25*E25 -> 18602.928 | Q25: 43241 | R25: 5000 | S25: 51.67 | T25: 96.768 | U25: 53.43 | V25: =T25*U25 -> 5170.3142
A26: 43069 | B26: 10000 | C26: 27.14 | D26: 368.46 | E26: 27.8889 | F26: =D26*E26 -> 10275.944 | Q26: 43256 | R26: 5000 | S26: 51.86 | T26: 96.413 | U26: 53.43 | V26: =T26*U26 -> 5151.3466
A27: 43081 | B27: 5000 | C27: 27.4795 | D27: 181.954 | E27: 27.8889 | F27: =D27*E27 -> 5074.4969 | Q27: 43279 | R27: 5000 | S27: 51.64 | T27: 96.824 | U27: 53.43 | V27: =T27*U27 -> 5173.3063
A28: 43130 | B28: 5000 | C28: 28.3192 | D28: 176.559 | E28: 27.8889 | F28: =D28*E28 -> 4924.0363 | J28: =SUM(J3:J27) -> 135000 | K28: =AVERAGE(K3:K27) -> 48.63515 | N28: =SUM(N3:N27) -> 151084.92
C29: =AVERAGE(C21:C28) -> 26.7265 | S29: =AVERAGE(S3:S27) -> 52.6916
R30: =SUM(R3:R27) -> 177000 | V30: =SUM(V3:V27) -> 179106.68
B31: =SUM(B21:B28) -> 265341.64 | D31: =SUM(D21:D28) -> 10301.416 | F31: =SUM(F21:F28) -> 287295.16
A34: Franklin india bluechip fund
B35: Invest | C35: nav | D35: units | E35: cur.Nav | F35: cur.Value
A36: 43237 | B36: 5000 | C36: 465.2674 | D36: 10.747 | E36: 472.5081 | F36: =D36*E36 -> 5078.0446
A37: 43238 | B37: 5000 | C37: 460.6376 | D37: 10.855 | E37: 472.5081 | F37: =D37*E37 -> 5129.0754
A38: 43241 | B38: 5000 | C38: 456.3792 | D38: 10.956 | E38: 472.5081 | F38: =D38*E38 -> 5176.7987
A43: ICICI Prudential Liquid Fund
B44: Invest | C44: nav | D44: units | E44: cur.Nav | F44: cur.Value
A45: 43534 | B45: 200000 | C45: 285.8594 | D45: 699.645 | E45: 291.4046 | F45: =E45*D45 -> 203879.77
A46: 43626 | B46: 100000 | C46: 286.0093 | D46: 349.639 | E46: 291.4046 | F46: =E46*D46 -> 101886.41

Sheet Networth
A1: 29135 | C1: EPS | D1: -113841 | X1: ppf | Y1: sahana
A2: 29501 | F2: =SUM(D29) -> 30447182 | J2: 40360 | K2: 541 | W2: 2012-13 | X2: 1
A3: 29866 | C3: pf int | F3: 1040000 | J3: 40391 | K3: 541 | M3: 100000 | N3: FD001577 | O3: 44520 | P3: 46346 | Q3: 0.1 | R3: =(M3*Q3)/12 -> 833.33333 | W3: 2013-14 | X3: 2 | Y3: LKG
A4: 30231 | C4: gratuity | F4: 1070806 | J4: 40422 | K4: 541 | M4: 100000 | N4: FD001576 | O4: 44517 | P4: 46343 | Q4: 0.1 | R4: =(M4*Q4)/12 -> 833.33333 | W4: 2014-15 | X4: 3 | Y4: UKG
A5: 30596 | C5: ppf | D5: 2761925 | E5: =D5*0.071 -> 196096.67 | J5: 40452 | K5: 541 | M5: 100000 | N5: FD001578 | O5: 44521 | P5: 46347 | Q5: 0.1 | R5: =(M5*Q5)/12 -> 833.33333 | W5: 2015-16 | X5: 4 | Y5: 1
A6: 30962 | C6: PF | D6: 3957500 | J6: 40483 | K6: 541 | M6: 100000 | N6: FD001579 | O6: 44523 | P6: 46349 | Q6: 0.1 | R6: =(M6*Q6)/12 -> 833.33333 | W6: 2016-17 | X6: 5 | Y6: 2
A7: 31327 | C7: VPF | D7: 552684 | J7: 40513 | K7: 541 | M7: 60000 | N7: FD001654 | O7: 44664 | P7: 46489 | Q7: 0.1 | R7: =(M7*Q7)/12 -> 500 | W7: 2017-18 | X7: 6 | Y7: 3
A8: 31692 | C8: unnati | D8: 1030000 | J8: 40544 | K8: 541 | M8: 60000 | N8: FD001652 | O8: 44664 | P8: 46489 | Q8: 0.1 | R8: =(M8*Q8)/12 -> 500 | W8: 2018-19 | X8: 7 | Y8: 4
A9: 32057 | C9: MF-debt | D9: 104503 | J9: 40575 | K9: 541 | M9: 60000 | N9: FD001651 | O9: 44664 | P9: 46489 | Q9: 0.1 | R9: =(M9*Q9)/12 -> 500 | W9: 2019-20 | X9: 8 | Y9: 5
A10: 32423 | C10: MF-cash | D10: 17881536 | J10: 40603 | K10: 541 | M10: 30000 | N10: FD001650 | O10: 44664 | P10: 46489 | Q10: 0.1 | R10: =(M10*Q10)/12 -> 250 | W10: 2020-21 | X10: 9 | Y10: 6
A11: 32788 | C11: MF-eq | D11: 927683 | J11: 40634 | K11: 541 | M11: 60000 | N11: FD001660 | O11: 44672 | P11: 46498 | Q11: 0.1 | R11: =(M11*Q11)/12 -> 500 | W11: 2021-22 | X11: 10 | Y11: 7
A12: 33153 | C12: axis | D12: 105298 | J12: 40664 | K12: 541 | M12: 60000 | N12: FD001661 | O12: 44672 | P12: 46498 | Q12: 0.1 | R12: =(M12*Q12)/12 -> 500 | W12: 2022-23 | X12: 11 | Y12: 8
A13: 33518 | C13: nirCanara | D13: 154340 | J13: 40695 | K13: 541 | M13: 60000 | N13: FD001662 | O13: 44672 | P13: 46498 | Q13: 0.1 | R13: =(M13*Q13)/12 -> 500 | W13: 2023-24 | X13: 12 | Y13: 9
A14: 33884 | C14: citizen | D14: 24000 | J14: 40725 | K14: 541 | M14: 60000 | N14: FD001689 | O14: 44717 | P14: 46572 | Q14: 0.1 | R14: =(M14*Q14)/12 -> 500 | W14: 2024-25 | X14: 13 | Y14: 10
A15: 34249 | C15: nirSBI | D15: 32470 | J15: 40756 | K15: 541 | M15: 30000 | N15: FD001709 | O15: 44766 | P15: 46591 | Q15: 0.1 | R15: =(M15*Q15)/12 -> 250 | W15: 2025-26 | X15: 14 | Y15: 11
A16: 34614 | C16: Shares | D16: 2500000 | J16: 40787 | K16: 541 | M16: 60000 | N16: FD001727 | O16: 44785 | P16: 46611 | Q16: 0.1 | R16: =(M16*Q16)/12 -> 500 | W16: 2026-27 | X16: 15 | Y16: 12
A17: 34979 | C17: Mom | D17: -1733.71 | J17: 40817 | K17: 541 | M17: 90000 | N17: FD001917 | O17: 45330 | P17: 47156 | Q17: =10/100 -> 0.1 | R17: =(M17*Q17)/12 -> 750 | W17: 2027-28 | X17: 16 | Y17: 13
A18: 35345 | C18: advance | D18: -340000 | J18: 40848 | K18: 541 | W18: 2028-29 | X18: 17 | Y18: 14
A19: 35710 | C19: lathaFD | D19: 550000 | J19: 40878 | K19: 541 | M19: =SUM(M1:M17) -> 1030000 | R19: =SUM(R1:R17) -> 8583.3333 | W19: 2029-30 | X19: 18 | Y19: 15
A20: 36075 | C20: lataCiti | D20: 0 | J20: 40909 | K20: 541 | W20: 2030-31 | X20: 19 | Y20: 16
A21: 36440 | C21: cc1 | D21: -51023 | J21: 40940 | K21: 541 | W21: 2031-32
A22: 36806 | D22: 48000 | J22: 40969 | K22: 541 | O22: 45702 | W22: 2032-33
A23: 37171 | C23: may | D23: 210000 | J23: 41000 | K23: 541 | O23: 444 | W23: 2033-34
A24: 37536 | J24: 41030 | K24: 541 | O24: =SUM(O22:O23) -> 46146 | W24: 2034-35
A25: 37901 | J25: 41061 | K25: 541
A26: 38267 | J26: 41091 | K26: 541
A27: 38632 | J27: 41122 | K27: 541
A28: 38997 | J28: 41153 | K28: 541
A29: 39362 | D29: =SUM(D2:D28) -> 30447182 | F29: =SUM(F2:F26) -> 32557988 | J29: 41183 | K29: 541
A30: 39728 | F30: 2915380 | J30: 41214 | K30: 541
A31: 40093 | F31: =SUM(F29:F30) -> 35473368 | J31: 41244 | K31: 541
A32: 40458 | J32: 41275 | K32: 541 | M32: Latha | S32: 46113 | T32: 46143 | U32: 46174 | V32: 46204 | W32: 46235 | X32: 46266 | Y32: 46296 | Z32: 46327 | AA32: 46357 | AB32: 46388 | AC32: 46419 | AD32: 46447 | AE32: 46478 | AF32: 46508 | AG32: 46539 | AH32: 46569 | AI32: 46600 | AJ32: 46631 | AK32: 46661 | AL32: 46692 | AM32: 46722 | AN32: 46753 | AO32: 46784 | AP32: 46813 | AQ32: 46844 | AR32: 46874 | AS32: 46905 | AT32: 46935 | AU32: 46966 | AV32: 46997
A33: 40823 | J33: 41306 | K33: 541 | M33: 200000 | N33: 120374 | O33: 46053 | P33: 46783 | Q33: 0.08 | R33: =(M33*Q33)/12 -> 1333.3333 | S33: 1333 | T33: 1333 | U33: 1333 | V33: 1333 | W33: 1333 | X33: 1333 | Y33: 1333 | Z33: 1333 | AA33: 1333 | AB33: 1333 | AC33: 1333 | AD33: 1333 | AE33: 1333 | AF33: 1333 | AG33: 1333 | AH33: 1333 | AI33: 1333 | AJ33: 1333 | AK33: 1333 | AL33: 1333 | AM33: 1333 | AN33: 1333
A34: 41189 | J34: 41334 | K34: 541 | M34: 100000 | N34: 120381 | O34: 46055 | P34: 46783 | Q34: 0.08 | R34: =(M34*Q34)/12 -> 666.66667 | S34: 667 | T34: 667 | U34: 667 | V34: 667 | W34: 667 | X34: 667 | Y34: 667 | Z34: 667 | AA34: 667 | AB34: 667 | AC34: 667 | AD34: 667 | AE34: 667 | AF34: 667 | AG34: 667 | AH34: 667 | AI34: 667 | AJ34: 667 | AK34: 667 | AL34: 667 | AM34: 667 | AN34: 667 | AO34: 667
A35: 41554 | J35: 41365 | K35: 541 | M35: 50000 | N35: 120391 | O35: 46065 | P35: 46795 | Q35: 0.08 | R35: =(M35*Q35)/12 -> 333.33333 | S35: 333 | T35: 333 | U35: 333 | V35: 333 | W35: 333 | X35: 333 | Y35: 333 | Z35: 333 | AA35: 333 | AB35: 333 | AC35: 333 | AD35: 333 | AE35: 333 | AF35: 333 | AG35: 333 | AH35: 333 | AI35: 333 | AJ35: 333 | AK35: 333 | AL35: 333 | AM35: 333 | AN35: 333 | AO35: 333
A36: 41919 | J36: 41395 | K36: 541 | M36: 50000 | N36: 120431 | O36: 46093 | P36: 46824 | Q36: 0.0055555556 | R36: 333.3333 | S36: 333 | T36: 333 | U36: 333 | V36: 333 | W36: 333 | X36: 333 | Y36: 333 | Z36: 333 | AA36: 333 | AB36: 333 | AC36: 333 | AD36: 333 | AE36: 333 | AF36: 333 | AG36: 333 | AH36: 333 | AI36: 333 | AJ36: 333 | AK36: 333 | AL36: 333 | AM36: 333 | AN36: 333 | AO36: 333 | AP36: 333
A37: 42284 | J37: 41426 | K37: 541 | M37: 50000 | N37: 120475 | O37: 46125 | P37: 46856 | Q37: 0.0055555556 | R37: 333.3333 | T37: 333 | U37: 333 | V37: 333 | W37: 333 | X37: 333 | Y37: 333 | Z37: 333 | AA37: 333 | AB37: 333 | AC37: 333 | AD37: 333 | AE37: 333 | AF37: 333 | AG37: 333 | AH37: 333 | AI37: 333 | AJ37: 333 | AK37: 333 | AL37: 333 | AM37: 333 | AN37: 333 | AO37: 333 | AP37: 333 | AQ37: 333
A38: 42650 | J38: 41456 | K38: 541 | M38: 50000 | N38: 120492 | O38: 46133 | P38: 46864 | Q38: 0.0055555556 | T38: 333 | U38: 333 | V38: 333 | W38: 333 | X38: 333 | Y38: 333 | Z38: 333 | AA38: 333 | AB38: 333 | AC38: 333 | AD38: 333 | AE38: 333 | AF38: 333 | AG38: 333 | AH38: 333 | AI38: 333 | AJ38: 333 | AK38: 333 | AL38: 333 | AM38: 333 | AN38: 333 | AO38: 333 | AP38: 333 | AQ38: 333
A39: 43015 | J39: 41487 | K39: 541 | M39: 50000 | N39: 120499 | O39: 46136 | P39: 46867 | Q39: 0.0055555556 | T39: 333 | U39: 333 | V39: 333 | W39: 333 | X39: 333 | Y39: 333 | Z39: 333 | AA39: 333 | AB39: 333 | AC39: 333 | AD39: 333 | AE39: 333 | AF39: 333 | AG39: 333 | AH39: 333 | AI39: 333 | AJ39: 333 | AK39: 333 | AL39: 333 | AM39: 333 | AN39: 333 | AO39: 333 | AP39: 333 | AQ39: 333
A40: 43380 | J40: 41518 | K40: 541
...

Sheet PF-VPF
A1: PF | B1: 2640218 | C1: Including Mar2022 contribution | V1: 40360 | W1: 38333 | X1: 1844 | Z1: 2640218 | AA1: 3631920 | AC1: 8.15
A2: VPF | B2: 512265 | C2: Including Mar2022 contribution | M2: 2432138 | V2: 40391 | W2: 38333 | X2: 1844 | Z2: 512265
A3: Wage Month | B3: PF | C3: compPF | D3: EPS | E3: gratuity | F3: vpf | H3: PF | I3: VPF | S3: Jan | V3: 40422 | W3: 38333 | X3: 1844 | Z3: Wage Month | AA3: PF | AB3: compPF | AC3: vpf | AD3: Balance
A4: 44652 | B4: 9729 | C4: 8479 | D4: 1250 | E4: 3900 | F4: 2619 | H4: =SUM(B1,B4,C4) -> 2658426 | I4: =SUM(B2,F4) -> 514884 | K4: 3.1 | L4: =SUM(B4:C4,E4:F4) -> 24727 | O4: 20827 | Q4: 202679 | S4: feb | V4: 40452 | W4: 38333 | X4: 1844 | Z4: 45017 | AA4: 10701 | AB4: 9451 | AC4: 2880 | AD4: =SUM(AA4:AC4,AA1) -> 3654952 | AE4: =(8.15*AA1)/1200 -> 24666.79
A5: 44682 | B5: 9729 | C5: 8479 | D5: 1250 | E5: 3900 | F5: 2619 | H5: =SUM(H4,B5,C5) -> 2676634 | I5: =SUM(I4,F5) -> 517503 | K5: 3.4 | L5: 143187 | O5: 155992 | Q5: -28980 | S5: mar | T5: carInsur | V5: 40483 | W5: 38333 | X5: 1844 | Z5: 45047 | AA5: 10701 | AB5: 9451 | AC5: 669 | AD5: =SUM(AA5:AC5,AD4) -> 3675773 | AE5: =(8.15*AD4)/1200 -> 24823.216
A6: 44713 | B6: 9729 | C6: 8479 | D6: 1250 | E6: 3900 | F6: 2619 | H6: =SUM(H5,B6,C6) -> 2694842 | I6: =SUM(I5,F6) -> 520122 | K6: 3.7 | L6: 2200 | O6: =SUM(O4:O5) -> 176819 | Q6: =SUM(Q4:Q5) -> 173699 | S6: apr | T6: propTax | U6: Fees | V6: 40513 | W6: 38333 | X6: 1844 | Z6: 45078 | AA6: 10701 | AB6: 9451 | AC6: 669 | AD6: =SUM(AA6:AC6,AD5) -> 3696594 | AE6: =(8.15*AD5)/1200 -> 24964.625
A7: 44743 | B7: 9729 | C7: 8479 | D7: 1250 | E7: 3900 | F7: 2619 | H7: =SUM(H6,B7,C7) -> 2713050 | I7: =SUM(I6,F7) -> 522741 | L7: =SUM(L4:L6) -> 170114 | O7: =2600000/O6 -> 14.704302 | S7: May | T7: Dress | U7: books | V7: 40544 | W7: 38333 | X7: 1844 | Z7: 45108 | AA7: 10701 | AB7: 9451 | AC7: 669 | AD7: =SUM(AA7:AC7,AD6) -> 3717415 | AE7: =(8.15*AD6)/1200 -> 25106.034
A8: 44774 | B8: 9729 | C8: 8479 | D8: 1250 | E8: 3900 | F8: 2619 | H8: =SUM(H7,B8,C8) -> 2731258 | I8: =SUM(I7,F8) -> 525360 | L8: 16500 | S8: June | V8: 40575 | W8: 38333 | X8: 1844 | Z8: 45139 | AA8: 10701 | AB8: 9451 | AC8: 669 | AD8: =SUM(AA8:AC8,AD7) -> 3738236 | AE8: =(8.15*AD7)/1200 -> 25247.444
A9: 44805 | B9: 9729 | C9: 8479 | D9: 1250 | E9: 3900 | F9: 2619 | H9: =SUM(H8,B9,C9) -> 2749466 | I9: =SUM(I8,F9) -> 527979 | L9: =SUM(L7:L8) -> 186614 | M9: =L9*12 -> 2239368 | S9: july | T9: tax | V9: 40603 | W9: 38333 | X9: 1844 | Z9: 45170 | AA9: 10701 | AB9: 9451 | AC9: 669 | AD9: =SUM(AA9:AC9,AD8) -> 3759057 | AE9: =(8.15*AD8)/1200 -> 25388.853
A10: 44835 | B10: 9729 | C10: 8479 | D10: 1250 | E10: 3900 | F10: 2619 | H10: =H9+B10+C10 -> 2767674 | I10: =SUM(I9,F10) -> 530598 | P10: =SUM(P11:P20) -> 172450 | S10: aug | V10: 40634 | W10: 38333 | X10: 1844 | Z10: 45200 | AA10: 10701 | AB10: 9451 | AC10: 669 | AD10: =SUM(AA10:AC10,AD9) -> 3779878 | AE10: =(8.15*AD9)/1200 -> 25530.262
A11: 44866 | B11: 9729 | C11: 8479 | D11: 1250 | E11: 3900 | F11: 2619 | H11: =SUM(H10,B11,C11) -> 2785882 | I11: =SUM(I10,F11) -> 533217 | N11: Nir | O11: latha | P11: 145523 | S11: Sep | V11: 40664 | W11: 38333 | X11: 1844 | Z11: 45231 | AA11: 10701 | AB11: 9451 | AC11: 669 | AD11: =SUM(AA11:AC11,AD10) -> 3800699 | AE11: =(8.15*AD10)/1200 -> 25671.671
A12: 44896 | B12: 9729 | C12: 8479 | D12: 1250 | E12: 3900 | F12: 2619 | H12: =SUM(H11,B12,C12) -> 2804090 | I12: =SUM(I11,F12) -> 535836 | M12: axis | P12: 9729 | S12: Oct | T12: Fees | U12: lic | V12: 40695 | W12: 38333 | X12: 1844 | Z12: 45261 | AA12: 10701 | AB12: 9451 | AC12: 669 | AD12: =SUM(AA12:AC12,AD11) -> 3821520 | AE12: =(8.15*AD11)/1200 -> 25813.081
A13: 44927 | B13: 10701 | C13: 9451 | D13: 1250 | E13: 4289 | F13: 2880 | H13: =SUM(H12,B13,C13) -> 2824242 | I13: =SUM(I12,F13) -> 538716 | M13: 45839 | N13: 2473 | P13: 2619 | S13: Nov | V13: 40725 | W13: 38333 | X13: 1844 | Z13: 45292 | AA13: 10701 | AB13: 9451 | AC13: 669 | AD13: =SUM(AA13:AC13,AD12) -> 3842341 | AE13: =(8.15*AD12)/1200 -> 25954.49
A14: 44958 | B14: 10701 | C14: 9451 | D14: 1250 | E14: 4289 | F14: 2880 | H14: =SUM(H13,B14,C14) -> 2844394 | I14: =SUM(I13,F14) -> 541596 | M14: 45931 | N14: 2828 | P14: 9729 | S14: Dec | V14: 40756 | W14: 38333 | X14: 1844 | Z14: 45323 | AA14: 11665 | AB14: 10415 | AC14: 729 | AD14: =SUM(AA14:AC14,AD13) -> 3865150 | AE14: =(8.15*AD13)/1200 -> 26095.899
A15: Int | H15: 245930 | M15: 46023 | N15: 2275 | P15: -1250 | V15: 40787 | W15: 38333 | X15: 1844 | Z15: 45352 | AA15: 11665 | AB15: 10415 | AC15: 729 | AD15: =SUM(AA15:AC15,AD14) -> 3887959 | AE15: =(8.15*AD14)/1200 -> 26250.81
A16: 44986 | B16: 10701 | C16: 9451 | D16: 1250 | E16: 4289 | F16: 2880 | H16: =SUM(H14:H15,B16,C16) -> 3110476 | I16: =SUM(I14,F16) -> 544476 | K16: =20152*12 -> 241824 | M16: 46112 | N16: 2357 | P16: 3900 | V16: 40817 | W16: 38333 | X16: 1844 | AE16: =SUM(AE4:AE15) -> 305513.18
A17: 45017 | B17: 10701 | C17: 9451 | D17: 1250 | E17: 4289 | F17: 669 | H17: =SUM(H16,B17,C17) -> 3130628 | I17: =SUM(I16,F17) -> 545145 | K17: =669*12 -> 8028 | M17: Canara | P17: 2200 | R17: 365 | S17: remaining | V17: 40848 | W17: 38333 | X17: 1844
A18: 45047 | B18: 10701 | C18: 9451 | D18: 1250 | E18: 4289 | F18: 669 | H18: =SUM(H17,B18,C18) -> 3150780 | I18: =SUM(I17,F18) -> 545814 | M18: 45836 | N18: 723 | O18: 1660 | S18: 9 | V18: 40878 | W18: 38333 | X18: 1844 | AD18: 3673696
A19: 45078 | B19: 10701 | C19: 9451 | D19: 1250 | E19: 4289 | F19: 669 | H19: =SUM(H18,B19,C19) -> 3170932 | I19: =SUM(I18,F19) -> 546483 | K19: =10701*2 -> 21402 | M19: 45927 | N19: 297 | O19: 798 | S19: 20 | V19: 40909 | W19: 38333 | X19: 1844 | AD19: 20821
A20: 45108 | B20: 10701 | C20: 9451 | D20: 1250 | E20: 4289 | F20: 669 | H20: =SUM(H19,B20,C20) -> 3191084 | I20: =SUM(I19,F20) -> 547152 | K20: 669 | M20: 46018 | N20: 499 | O20: 254 | V20: 40940 | W20: 42167 | X20: 2028 | AD20: =SUM(AD18:AD19) -> 3694517
A21: 45139 | B21: 10701 | C21: 9451 | D21: 1250 | E21: 4289 | F21: 669 | H21: =SUM(H20,B21,C21) -> 3211236 | I21: =SUM(I20,F21) -> 547821 | K21: =SUM(K19:K20) -> 22071 | N21: 468 | O21: 655 | P21: 162634 | Q21: =P21*2 -> 325268 | R21: =20821*2 -> 41642 | V21: 40969 | W21: 42167 | X21: 2028
A22: 45170 | B22: 10701 | C22: 9451 | D22: 1250 | E22: 4289 | F22: 669 | H22: =SUM(H21,B22,C22) -> 3231388 | I22: =SUM(I21,F22) -> 548490 | K22: -1250 | P22: 20152 | V22: 41000 | W22: 42167 | X22: 2028
A23: 45200 | B23: 10701 | C23: 9451 | D23: 1250 | E23: 4289 | F23: 669 | H23: =SUM(H22,B23,C23) -> 3251540 | I23: =SUM(I22,F23) -> 549159 | K23: =SUM(K21:K22) -> 20821 | M23: Citizen | P23: 669 | V23: 41030 | W23: 42167 | X23: 2028 | Z23: 375912 | AB23: pf | AC23: 266924
A24: 45231 | B24: 10701 | C24: 9451 | D24: 1250 | E24: 4289 | F24: 669 | H24: =SUM(H23,B24,C24) -> 3271692 | I24: =SUM(I23,F24) -> 549828 | M24: 45565 | N24: 674 | P24: 16300 | R24: =29/6 -> 4.8333333 | S24: 155000 | V24: 41061 | W24: 42167 | X24: 2028 | Z24: 16470 | AB24: ppf | AC24: 113051
A25: 45261 | B25: 10701 | C25: 9451 | D25: 1250 | E25: 4289 | F25: 669 | H25: =SUM(H24,B25,C25) -> 3291844 | I25: =SUM(I24,F25) -> 550497 | M25: 45747 | N25: 350 | P25: 2200 | S25: 23032 | V25: 41091 | W25: 42167 | X25: 2028 | Z25: =SUM(Z23:Z24) -> 392382 | AC25: 1806536
A26: 45292 | B26: 11665 | C26: 10415 | D26: 1250 | E26: 4675 | F26: 729 | H26: =SUM(H25,B26,C26) -> 3313924 | I26: =SUM(I25,F26) -> 551226 | M26: SBI | S26: 16300 | V26: 41122 | W26: 42167 | X26: 2028 | Z26: =SUM(AC23:AC24) -> 379975 | AB26: pf | AC26: 119664
A27: 45323 | B27: 11665 | C27: 10415 | D27: 1250 | E27: 4675 | F27: 729 | H27: =SUM(H26,B27,C27) -> 3336004 | I27: =SUM(I26,F27) -> 551955 | K27: =SUM(H27:I27) -> 3887959 | M27: 45468 | N27: 180 | Q27: 81071 | R27: =Q27*0.4 -> 32428.4 | S27: 2200 | V27: 41153 | W27: 42167 | X27: 2028 | Z27: =Z25-Z26 -> 12407 | AC27: 32211
A28: int | H28: 0 | K28: =K27*0.0825 -> 320756.62 | M28: 45560 | N28: 128 | R28: =Q27*0.5 -> 40535.5 | S28: =SUM(S24:S27) -> 196532 | V28: 41183 | W28: 42167 | X28: 2028 | AC28: -15000
A29: 45352 | B29: 11665 | C29: 10415 | D29: 1250 | E29: 4675 | F29: 729 | H29: =SUM(H27,B29,C29) -> 3358084 | I29: =SUM(I27,F29) -> 552684 | M29: 45651 | N29: 712 | V29: 41214 | W29: 42167 | X29: 2028 | AC29: 119664
A30: 45383 | B30: 11665 | C30: 10415 | D30: 1250 | E30: 4675 | F30: 0 | H30: =SUM(H29,B30,C30) -> 3380164 | I30: =SUM(I29,F30) -> 552684 | M30: 45741 | N30: 198 | V30: 41244 | W30: 42167 | X30: 2028 | AC30: =2200*12 -> 26400
A31: 45413 | B31: 11665 | C31: 10415 | D31: 1250 | E31: 4675 | F31: 0 | H31: =SUM(H30,B31,C31) -> 3402244 | I31: =SUM(I30,F31) -> 552684 | N31: =SUM(N13:N16,N18:N21,N24:N25,N27:N30) -> 14162 | Q31: 28979 | R31: =Q31*12 -> 347748 | V31: 41275 | W31: 42167 | X31: 2028 | AC31: =SUM(AC23:AC30) -> 2469450
A32: 45444 | B32: 11665 | C32: 10415 | D32: 1250 | E32: 4675 | F32: 0 | H32: =SUM(H31,B32,C32) -> 3424324 | I32: =SUM(I31,F32) -> 552684 | V32: 41306 | W32: 44275 | X32: 2130
A33: 45474 | B33: 11665 | C33: 10415 | D33: 1250 | E33: 4675 | F33: 0 | H33: =SUM(H32,B33,C33) -> 3446404 | I33: =SUM(I31,F33) -> 552684 | M33: kothari Products | O33: sold on | P33: 45300 | V33: 41334 | W33: 44275 | X33: 2130
A34: 45505 | B34: 11665 | C34: 10415 | D34: 1250 | E34: 4675 | F34: 0 | H34: =SUM(H33,B34,C34) -> 3468484 | I34: =SUM(I33,F34) -> 552684 | V34: 41365 | W34: 44275 | X34: 2130
A35: 45536 | B35: 11665 | C35: 10415 | D35: 1250 | E35: 4675 | F35: 0 | H35: =SUM(H34,B35,C35) -> 3490564 | I35: =SUM(I33,F35) -> 552684 | M35: =SUM(O18:O20) -> 2712 | V35: 41395 | W35: 44275 | X35: 2130
A36: 45566 | B36: 11665 | C36: 10415 | D36: 1250 | E36: 4675 | F36: 0 | H36: =SUM(H35,B36,C36) -> 3512644 | I36: =SUM(I35,F36) -> 552684 | L36: latha | M36: int frm FD | V36: 41426 | W36: 44275 | X36: 2130
A37: 45597 | B37: 11665 | C37: 10415 | D37: 1250 | E37: 4675 | F37: 0 | H37: =SUM(H36,B37,C37) -> 3534724 | I37: =SUM(I36,F37) -> 552684 | L37: 45788 | M37: 884 | V37: 41456 | W37: 44275 | X37: 2130
A38: 45627 | B38: 11665 | C38: 10415 | D38: 1250 | E38: 4675 | F38: 0 | H38: =SUM(H37,B38,C38) -> 3556804 | I38: =SUM(I37,F38) -> 552684 | L38: 45880 | M38: 914 | V38: 41487 | W38: 44275 | X38: 2130
A39: 45658 | B39: 12889 | C39: 11639 | D39: 1250 | E39: 5166 | F39: 0 | H39: =SUM(H38,B39,C39) -> 3581332 | I39: 552684 | L39: 45972 | M39: 914 | V39: 41518 | W39: 44275 | X39: 2130
A40: 45689 | B40: 12889 | C40: 11639 | D40: 1250 | E40: 5166 | F40: 0 | H40: =SUM(H39,B40,C40) -> 3605860 | I40: 552684 | L40: 46051 | M40: 785 | V40: 41548 | W40: 44275 | X40: 2130
...

Sheet car
B1: =SUM(B2:B6) -> 149024 | I1: 2241601 | J1: =I1*0.085 -> 190536.09 | K1: =I1+J1 -> 2432137.1 | L1: =K1*(1.68/100) -> 40859.903 | P1: basic | Q1: 81071 | R1: =Q1*0.4 -> 32428.4 | T1: 81071 | W1: 2432136 | Z1: 2675350 | AA1: =Z1*0.08 -> 214028 | AD1: 3480113 | AE1: 0.1 | AF1: 0.09 | AG1: 0.08 | AH1: 0.07 | AI1: 0.06 | AJ1: 0.05 | AP1: Unnati
B2: -2983 | C2: 815128 | D2: =C2/12 -> 67927.333 | E2: 67927 | F2: =E2*0.12 -> 8151.24 | I2: 6793 | J2: 8151 | K2: -1250 | P2: HRA | Q2: 40536 | R2: fixed | T2: 40536 | W2: =W1/12 -> 202678 | Z2: -400000 | AA2: =Z1*0.09 -> 240781.5 | AB2: =Z1+AA2 -> 2916131.5 | AE2: =AD1*AE1 -> 348011.3 | AF2: =AD1*AF1 -> 313210.17 | AG2: =AD1*AG1 -> 278409.04 | AH2: =AD1*AH1 -> 243607.91 | AI2: =AD1*AI1 -> 208806.78 | AJ2: =AD1*AJ1 -> 174005.65 | AM2: 42005 | AO2: 42736 | AP2: 13000 | AQ2: 43466 | AR2: 14500 | AS2: 44197 | AT2: 14900 | AU2: 44927 | AV2: 16300 | AY2: 41368267950 | AZ2: 98000
B3: -27114 | C3: 1085664 | D3: 89072 | E3: =C3/12 -> 90472 | F3: =SUM(D8:D12) -> 40800 | G3: =E3-F3 -> 49672 | I3: 111455 | J3: =SUM(I2:K2) -> 13694 | K3: 17661 | L3: 2000 | M3: 3267 | N3: 2000 | O3: 1400 | P3: bonus | Q3: 1400 | R3: fixed | T3: 1400 | W3: -30000 | X3: =W1*0.1 -> 243213.6 | Y3: =W1+X3 -> 2675349.6 | Z3: =SUM(Z1:Z2) -> 2275350 | AA3: =Z1*0.1 -> 267535 | AE3: =SUM(AD1,AE2) -> 3828124.3 | AF3: =SUM(AF2,AD1) -> 3793323.2 | AG3: =SUM(AG2,AD1) -> 3758522 | AH3: =SUM(AH2,AD1) -> 3723720.9 | AM3: 42036 | AO3: 42767 | AQ3: 43497 | AR3: 14800 | AS3: 44228 | AT3: 16000 | AU3: 44958 | AV3: 16300 | AY3: 42446106429 | AZ3: 49000
